<?xml version="1.0" ?>
<!-- =================================================================================== -->
<!-- |    This document was autogenerated by xacro from fanuc_leaphand.xacro           | -->
<!-- |    EDITING THIS FILE BY HAND IS NOT RECOMMENDED                                 | -->
<!-- =================================================================================== -->
<robot name="fanuc_arm_leap_hand">
  <material name="Yellow">
    <color rgba="1.0  1.0  0.0  1.0"/>
  </material>
  <material name="Black">
    <color rgba="0.0  0.0  0.0  1.0"/>
  </material>
  <material name="Gray">
    <color rgba="0.5  0.5  0.5  1.0"/>
  </material>
  <material name="Gray_2">
    <color rgba="1.0  1.0  1.0  1.0"/>
  </material>
  <link name="base">
    <inertial>
      <origin rpy="0.0  0.0  0.0" xyz="0.0  0.0  0.0"/>
      <mass value="0.0"/>
      <inertia ixx="0.0" ixy="0.0" ixz="0.0" iyy="0.0" iyz="0.0" izz="0.0"/>
    </inertial>
    <visual name="base">
      <origin rpy="0.0  0.0  0.0" xyz="0.000   0.000   0.330"/>
      <geometry>
        <mesh filename="./fanuc/CAD/base.stl" scale="0.001   0.001   0.001"/>
      </geometry>
      <material name="Gray"/>
    </visual>
    <collision>
      <origin rpy="0.0  0.0  0.0" xyz="0.000   0.000   0.330"/>
      <geometry>
        <mesh filename="./fanuc/CAD/base.stl" scale="0.001   0.001   0.001"/>
      </geometry>
    </collision>
  </link>
  <joint name="joint_1" type="revolute">
    <origin rpy="0.0000000000000000    0.0000000000000000    0.0000000000000000" xyz="0.000   0.000   0.330"/>
    <parent link="base"/>
    <child link="link_1"/>
    <axis xyz="0 0 1"/>
    <limit effort="224.1470270270270646" lower="-3.1415926535897931" upper="3.1415926535897931" velocity="0.8726646259971648"/>
  </joint>
  <link name="link_1">
    <inertial>
      <origin rpy="-1.5707963267948966    0.0000000000000000    0.0000000000000000" xyz="0.0185909590000000    0.0033700950000000   -0.0770907100000000"/>
      <mass value="2.3984700000000001"/>
      <inertia ixx="0.0233179728630000" ixy="0.0000000000000000" ixz="0.0000000000000000" iyy="0.0193776178710000" iyz="0.0000000000000000" izz="0.0139141526340000"/>
    </inertial>
    <visual name="link_1">
      <origin rpy="-1.5707963267948966    0.0000000000000000    0.0000000000000000" xyz="0.050   0.000   0.000"/>
      <geometry>
        <mesh filename="./fanuc/CAD/link1.stl" scale="0.001   0.001   0.001"/>
      </geometry>
      <material name="Yellow"/>
    </visual>
    <collision>
      <origin rpy="-1.5707963267948966    0.0000000000000000    0.0000000000000000" xyz="0.050   0.000   0.000"/>
      <geometry>
        <mesh filename="./fanuc/CAD/link1.stl" scale="0.001   0.001   0.001"/>
      </geometry>
    </collision>
  </link>
  <joint name="joint_2" type="revolute">
    <origin rpy="-1.5707963267948966    0.0000000000000000    0.0000000000000000" xyz="0.050   0.000   0.000"/>
    <parent link="link_1"/>
    <child link="link_2"/>
    <axis xyz="0 0 1"/>
    <limit effort="236.6760000000000161" lower="-3.1415926535897931" upper="3.1415926535897931" velocity="0.8726646259971648"/>
  </joint>
  <link name="link_2">
    <inertial>
      <origin rpy="3.1415926535897931    0.0000000000000000   -1.5707963267948966" xyz="-0.0071079890000000   -0.1326139250000000    0.0247800790000000"/>
      <mass value="7.8018689999999999"/>
      <inertia ixx="0.0328971739050000" ixy="0.0000000000000000" ixz="0.0000000000000000" iyy="0.2070365793270000" iyz="0.0000000000000000" izz="0.1883991938960000"/>
    </inertial>
    <visual name="link_2">
      <origin rpy="3.1415926535897931    0.0000000000000000   -1.5707963267948966" xyz="0.000  -0.440   0.000"/>
      <geometry>
        <mesh filename="./fanuc/CAD/link2.stl" scale="0.001   0.001   0.001"/>
      </geometry>
      <material name="Yellow"/>
    </visual>
    <collision>
      <origin rpy="3.1415926535897931    0.0000000000000000   -1.5707963267948966" xyz="0.000  -0.440   0.000"/>
      <geometry>
        <mesh filename="./fanuc/CAD/link2.stl" scale="0.001   0.001   0.001"/>
      </geometry>
    </collision>
  </link>
  <joint name="joint_3" type="revolute">
    <origin rpy="3.1415926535897931    0.0000000000000000   -1.5707963267948966" xyz="0.000  -0.440   0.000"/>
    <parent link="link_2"/>
    <child link="link_3"/>
    <axis xyz="0 0 1"/>
    <limit effort="94.9241379310344939" lower="-3.1415926535897931" upper="3.1415926535897931" velocity="0.8726646259971648"/>
  </joint>
  <link name="link_3">
    <inertial>
      <origin rpy="-1.5707963267948966    0.0000000000000000    0.0000000000000000" xyz="0.0057931330000000   -0.0059066300000000   -0.0207324280000000"/>
      <mass value="2.9847210000000000"/>
      <inertia ixx="0.0081019474240000" ixy="0.0000000000000000" ixz="0.0000000000000000" iyy="0.0068697082660000" iyz="0.0000000000000000" izz="0.0079818513480000"/>
    </inertial>
    <visual name="link_3">
      <origin rpy="-1.5707963267948966    0.0000000000000000    0.0000000000000000" xyz="0.035   0.000   0.000"/>
      <geometry>
        <mesh filename="./fanuc/CAD/link3.stl" scale="0.001   0.001   0.001"/>
      </geometry>
      <material name="Yellow"/>
    </visual>
    <collision>
      <origin rpy="-1.5707963267948966    0.0000000000000000    0.0000000000000000" xyz="0.035   0.000   0.000"/>
      <geometry>
        <mesh filename="./fanuc/CAD/link3.stl" scale="0.001   0.001   0.001"/>
      </geometry>
    </collision>
  </link>
  <joint name="joint_4" type="revolute">
    <origin rpy="-1.5707963267948966    0.0000000000000000    0.0000000000000000" xyz="0.035   0.000   0.000"/>
    <parent link="link_3"/>
    <child link="link_4"/>
    <axis xyz="0 0 1"/>
    <limit effort="23.8998260869565229" lower="-3.1415926535897931" upper="3.1415926535897931" velocity="0.8726646259971648"/>
  </joint>
  <link name="link_4">
    <inertial>
      <origin rpy="1.5707963267948966    0.0000000000000000    0.0000000000000000" xyz="-0.0002457140000000    0.0028224150000000   -0.2060611280000000"/>
      <mass value="4.1441780000000001"/>
      <inertia ixx="0.0529101059260000" ixy="0.0000000000000000" ixz="0.0000000000000000" iyy="0.0057046189630000" iyz="0.0000000000000000" izz="0.0531509714450000"/>
    </inertial>
    <visual name="link_4">
      <origin rpy="1.5707963267948966    0.0000000000000000    0.0000000000000000" xyz="0.000   0.000  -0.420"/>
      <geometry>
        <mesh filename="./fanuc/CAD/link4.stl" scale="0.001   0.001   0.001"/>
      </geometry>
      <material name="Yellow"/>
    </visual>
    <collision>
      <origin rpy="1.5707963267948966    0.0000000000000000    0.0000000000000000" xyz="0.000   0.000  -0.420"/>
      <geometry>
        <mesh filename="./fanuc/CAD/link4.stl" scale="0.001   0.001   0.001"/>
      </geometry>
    </collision>
  </link>
  <joint name="joint_5" type="revolute">
    <origin rpy="1.5707963267948966    0.0000000000000000    0.0000000000000000" xyz="0.000   0.000  -0.420"/>
    <parent link="link_4"/>
    <child link="link_5"/>
    <axis xyz="0 0 1"/>
    <limit effort="13.8166666666666664" lower="-3.1415926535897931" upper="3.1415926535897931" velocity="0.8726646259971648"/>
  </joint>
  <link name="link_5">
    <inertial>
      <origin rpy="-1.5707963267948966    0.0000000000000000    0.0000000000000000" xyz="0.0000480440000000   -0.0273839680000000   -0.0044381510000000"/>
      <mass value="1.8704200000000000"/>
      <inertia ixx="0.0024795564500000" ixy="0.0000000000000000" ixz="0.0000000000000000" iyy="0.0024375453070000" iyz="0.0000000000000000" izz="0.0012003431970000"/>
    </inertial>
    <visual name="link_5">
      <origin rpy="-1.5707963267948966    0.0000000000000000    0.0000000000000000" xyz="0.000   0.000   0.000"/>
      <geometry>
        <mesh filename="./fanuc/CAD/link5.stl" scale="0.001   0.001   0.001"/>
      </geometry>
      <material name="Yellow"/>
    </visual>
    <collision>
      <origin rpy="-1.5707963267948966    0.0000000000000000    0.0000000000000000" xyz="0.000   0.000   0.000"/>
      <geometry>
        <mesh filename="./fanuc/CAD/link5.stl" scale="0.001   0.001   0.001"/>
      </geometry>
    </collision>
  </link>
  <joint name="joint_6" type="revolute">
    <origin rpy="0.0 1.5707963267948966 0.0" xyz="0 -0.08 0.0"/>
    <parent link="link_5"/>
    <child link="link_6"/>
    <axis xyz="0 1 0"/>
    <limit effort="6.8606896551724139" lower="-3.1415926535897931" upper="3.1415926535897931" velocity="0.8726646259971648"/>
  </joint>
  <link name="link_6">
    <inertial>
      <origin rpy="0 0 0" xyz="0 0 0.04"/>
      <mass value=".81"/>
      <inertia ixx="0.1" ixy="0" ixz="0" iyy="0.1" iyz="0" izz="0.1"/>
    </inertial>
  </link>
  <joint name="link6_to_ee" type="fixed">
    <origin rpy="1.5707963267948966 0 0" xyz="0 -0.063 0"/>
    <parent link="link_6"/>
    <child link="end_effector"/>
  </joint>
  <link name="end_effector"/>
  <link name="palm_lower">
    <visual>
      <origin rpy="0 -0 0" xyz="-0.020095249652862544332 0.025757756134899473244 -0.034722403578460216134"/>
      <geometry>
        <mesh filename="./leap_hand/mesh/palm_lower.stl"/>
      </geometry>
      <material name="palm_lower_material">
        <color rgba="0.60392156862745094426 0.14901960784313725283 0.14901960784313725283 1.0"/>
      </material>
    </visual>
    <collision>
      <origin rpy="0 -0 0" xyz="-0.020095249652862544332 0.025757756134899473244 -0.034722403578460216134"/>
      <geometry>
        <mesh filename="./leap_hand/mesh/palm_lower.stl"/>
      </geometry>
    </collision>
    <inertial>
      <origin rpy="0 0 0" xyz="0 0 0"/>
      <mass value="0.237"/>
      <inertia ixx="0.000354094" ixy="-0.000001193" ixz="-0.000002445" iyy="0.000260915" iyz="-0.000002905" izz="0.000529257"/>
    </inertial>
  </link>
  <link name="mcp_joint">
    <visual>
      <origin rpy="1.6375789613220999807e-15 -1.0210473302491019535e-30 1.7177968783327987474e-31" xyz="0.0084069022611744960438 0.0077662438597169954416 0.014657354985032912051"/>
      <geometry>
        <mesh filename="./leap_hand/mesh/mcp_joint.stl"/>
      </geometry>
      <material name="mcp_joint_material">
        <color rgba="0.86666666666666669627 0.86666666666666669627 0.050980392156862744391 1.0"/>
      </material>
    </visual>
    <collision>
      <origin rpy="1.6375789613220999807e-15 -1.0210473302491019535e-30 1.7177968783327987474e-31" xyz="0.0084069022611744960438 0.0077662438597169954416 0.014657354985032912051"/>
      <geometry>
        <mesh filename="./leap_hand/mesh/mcp_joint.stl"/>
      </geometry>
    </collision>
    <inertial>
      <origin rpy="0 0 0" xyz="0 0 0"/>
      <mass value="0.044"/>
      <inertia ixx="0.000011499" ixy="0.000003049" ixz="0.000000121" iyy="0.000007796" iyz="0.000000112" izz="0.000014759"/>
    </inertial>
  </link>
  <link name="pip">
    <visual>
      <origin rpy="-1.570796326794896558 -1.570796326794896336 0" xyz="0.0096433630922713280131 0.00029999999999998951117 0.00078403401041737645627"/>
      <geometry>
        <mesh filename="./leap_hand/mesh/pip.stl"/>
      </geometry>
      <material name="pip_material">
        <color rgba="0.74901960784313725839 0.74901960784313725839 0.74901960784313725839 1.0"/>
      </material>
    </visual>
    <collision>
      <origin rpy="-1.570796326794896558 -1.570796326794896336 0" xyz="0.0096433630922713280131 0.00029999999999998951117 0.00078403401041737645627"/>
      <geometry>
        <mesh filename="./leap_hand/mesh/pip.stl"/>
      </geometry>
    </collision>
    <inertial>
      <origin rpy="0 0 0" xyz="0 0 0"/>
      <mass value="0.032"/>
      <inertia ixx="0.000004798" ixy="0.000000012" ixz="0.000000004" iyy="0.000002862" iyz="0.000000011" izz="0.000004234"/>
    </inertial>
  </link>
  <link name="dip">
    <visual>
      <origin rpy="-3.141592653589793116 4.5075111242164408299e-32 4.4395481053923607589e-32" xyz="0.021133352895225002849 -0.0084321191467048792201 0.0097850881620952408213"/>
      <geometry>
        <mesh filename="./leap_hand/mesh/dip.stl"/>
      </geometry>
      <material name="dip_material">
        <color rgba="0.86666666666666669627 0.86666666666666669627 0.050980392156862744391 1.0"/>
      </material>
    </visual>
    <collision>
      <origin rpy="-3.141592653589793116 4.5075111242164408299e-32 4.4395481053923607589e-32" xyz="0.021133352895225002849 -0.0084321191467048792201 0.0097850881620952408213"/>
      <geometry>
        <mesh filename="./leap_hand/mesh/dip.stl"/>
      </geometry>
    </collision>
    <inertial>
      <origin rpy="0 0 0" xyz="0 0 0"/>
      <mass value="0.037"/>
      <inertia ixx="0.000005542" ixy="-0.000000607" ixz="-0.000000017" iyy="0.000005727" iyz="-0.000000023" izz="0.000006682"/>
    </inertial>
  </link>
  <link name="fingertip">
    <visual>
      <origin rpy="3.141592653589793116 1.1993117970061734707e-33 4.4395481053923607589e-32" xyz="0.013286424108533503169 -0.0061142383865419869249 0.014499999999999497666"/>
      <geometry>
        <mesh filename="./leap_hand/mesh/fingertip_gelsight.STL"/>
      </geometry>
      <material name="fingertip_material">
        <color rgba="0.86666666666666669627 0.86666666666666669627 0.050980392156862744391 1.0"/>
      </material>
    </visual>
    <collision>
      <origin rpy="3.141592653589793116 1.1993117970061734707e-33 4.4395481053923607589e-32" xyz="0.013286424108533503169 -0.0061142383865419869249 0.014499999999999497666"/>
      <geometry>
        <mesh filename="./leap_hand/mesh/fingertip_gelsight.STL"/>
      </geometry>
    </collision>
    <inertial>
      <origin rpy="0 0 0" xyz="0 0 0"/>
      <mass value="0.016"/>
      <inertia ixx="0.000003368" ixy="0.000000115" ixz="0" iyy="0.000001556" iyz="0" izz="0.000002863"/>
    </inertial>
  </link>
  <joint name="0" type="revolute">
    <origin rpy="-1.570796326794896558 -1.0065212660796336576e-15 1.5707963267948943376" xyz="-0.012200000000000007713 0.038099999999999994982 0.014500000000000000736"/>
    <parent link="mcp_joint"/>
    <child link="pip"/>
    <axis xyz="0 0 -1"/>
    <limit effort="0.95" lower="-1.047" upper="1.047" velocity="8.48"/>
    <joint_properties friction="0.0"/>
  </joint>
  <joint name="1" type="revolute">
    <origin rpy="1.5707963267948950037 1.5707963267948945596 0" xyz="-0.0070952496528625457958 0.023057756134899472233 -0.01872240357846021927"/>
    <parent link="palm_lower"/>
    <child link="mcp_joint"/>
    <axis xyz="0 0 -1"/>
    <limit effort="0.95" lower="-0.314" upper="2.23" velocity="8.48"/>
    <joint_properties friction="0.0"/>
  </joint>
  <joint name="2" type="revolute">
    <origin rpy="1.5707963267948958919 -1.570796326794896336 0" xyz="0.01499999999999996822 0.014299999999999904801 -0.012999999999999824196"/>
    <parent link="pip"/>
    <child link="dip"/>
    <axis xyz="0 0 -1"/>
    <limit effort="0.95" lower="-0.506" upper="1.885" velocity="8.48"/>
    <joint_properties friction="0.0"/>
  </joint>
  <joint name="3" type="revolute">
    <origin rpy="4.5935029425113685044e-17 -2.8730071914463794583e-16 4.4395481053923607589e-32" xyz="-4.0880582495572692636e-09 -0.036100004210367367397 0.00020000000000007858714"/>
    <parent link="dip"/>
    <child link="fingertip"/>
    <axis xyz="0 0 -1"/>
    <limit effort="0.95" lower="-0.366" upper="2.042" velocity="8.48"/>
    <joint_properties friction="0.0"/>
  </joint>
  <link name="mcp_joint_2">
    <visual>
      <origin rpy="1.6375789613220999807e-15 -1.0076465469034000467e-30 2.1209300131419907151e-61" xyz="0.0084069022611744960438 0.0077662438597169954416 0.014657354985032913786"/>
      <geometry>
        <mesh filename="./leap_hand/mesh/mcp_joint.stl"/>
      </geometry>
      <material name="mcp_joint_material">
        <color rgba="0.86666666666666669627 0.86666666666666669627 0.050980392156862744391 1.0"/>
      </material>
    </visual>
    <collision>
      <origin rpy="1.6375789613220999807e-15 -1.0076465469034000467e-30 2.1209300131419907151e-61" xyz="0.0084069022611744960438 0.0077662438597169954416 0.014657354985032913786"/>
      <geometry>
        <mesh filename="./leap_hand/mesh/mcp_joint.stl"/>
      </geometry>
    </collision>
    <inertial>
      <origin rpy="0 0 0" xyz="0 0 0"/>
      <mass value="0.044"/>
      <inertia ixx="0.000011499" ixy="0.000003049" ixz="0.000000121" iyy="0.000007796" iyz="0.000000112" izz="0.000014759"/>
    </inertial>
  </link>
  <link name="pip_2">
    <visual>
      <origin rpy="-1.570796326794896558 -1.570796326794896336 0" xyz="0.0096433630922713280131 0.00029999999999999471534 0.00078403401041737645627"/>
      <geometry>
        <mesh filename="./leap_hand/mesh/pip.stl"/>
      </geometry>
      <material name="pip_material">
        <color rgba="0.74901960784313725839 0.74901960784313725839 0.74901960784313725839 1.0"/>
      </material>
    </visual>
    <collision>
      <origin rpy="-1.570796326794896558 -1.570796326794896336 0" xyz="0.0096433630922713280131 0.00029999999999999471534 0.00078403401041737645627"/>
      <geometry>
        <mesh filename="./leap_hand/mesh/pip.stl"/>
      </geometry>
    </collision>
    <inertial>
      <origin rpy="0 0 0" xyz="0 0 0"/>
      <mass value="0.032"/>
      <inertia ixx="0.000004798" ixy="0.000000012" ixz="0.000000004" iyy="0.000002862" iyz="0.000000011" izz="0.000004234"/>
    </inertial>
  </link>
  <link name="dip_2">
    <visual>
      <origin rpy="-3.141592653589793116 2.1146933785271955805e-32 1.4408183216511868558e-31" xyz="0.021133352895225002849 -0.0084321191467048653423 0.0097850881620952373519"/>
      <geometry>
        <mesh filename="./leap_hand/mesh/dip.stl"/>
      </geometry>
      <material name="dip_material">
        <color rgba="0.86666666666666669627 0.86666666666666669627 0.050980392156862744391 1.0"/>
      </material>
    </visual>
    <collision>
      <origin rpy="-3.141592653589793116 2.1146933785271955805e-32 1.4408183216511868558e-31" xyz="0.021133352895225002849 -0.0084321191467048653423 0.0097850881620952373519"/>
      <geometry>
        <mesh filename="./leap_hand/mesh/dip.stl"/>
      </geometry>
    </collision>
    <inertial>
      <origin rpy="0 0 0" xyz="0 0 0"/>
      <mass value="0.037"/>
      <inertia ixx="0.000005542" ixy="-0.000000607" ixz="-0.000000017" iyy="0.000005727" iyz="-0.000000023" izz="0.000006682"/>
    </inertial>
  </link>
  <link name="fingertip_2">
    <visual>
      <origin rpy="3.141592653589793116 -4.3179597882835943107e-33 1.4408183216511868558e-31" xyz="0.01328642410853349623 -0.0061142383865420008027 0.014499999999999495931"/>
      <geometry>
        <mesh filename="./leap_hand/mesh/fingertip.stl"/>
      </geometry>
      <material name="fingertip_material">
        <color rgba="0.86666666666666669627 0.86666666666666669627 0.050980392156862744391 1.0"/>
      </material>
    </visual>
    <collision>
      <origin rpy="3.141592653589793116 -4.3179597882835943107e-33 1.4408183216511868558e-31" xyz="0.01328642410853349623 -0.0061142383865420008027 0.014499999999999495931"/>
      <geometry>
        <mesh filename="./leap_hand/mesh/fingertip.stl"/>
      </geometry>
    </collision>
    <inertial>
      <origin rpy="0 0 0" xyz="0 0 0"/>
      <mass value="0.016"/>
      <inertia ixx="0.000003368" ixy="0.000000115" ixz="0" iyy="0.000001556" iyz="0" izz="0.000002863"/>
    </inertial>
  </link>
  <joint name="4" type="revolute">
    <origin rpy="-1.570796326794896558 -1.0065212760057939085e-15 1.5707963267948943376" xyz="-0.012200000000000019856 0.038099999999999981104 0.01450000000000000594"/>
    <parent link="mcp_joint_2"/>
    <child link="pip_2"/>
    <axis xyz="0 0 -1"/>
    <limit effort="0.95" lower="-1.047" upper="1.047" velocity="8.48"/>
    <joint_properties friction="0.0"/>
  </joint>
  <joint name="5" type="revolute">
    <origin rpy="1.570796326794896558 1.570796326794896558 0" xyz="-0.0070952496528625388569 -0.022392243865100525113 -0.018722403578460229678"/>
    <parent link="palm_lower"/>
    <child link="mcp_joint_2"/>
    <axis xyz="0 0 -1"/>
    <limit effort="0.95" lower="-0.314" upper="2.23" velocity="8.48"/>
    <joint_properties friction="0.0"/>
  </joint>
  <joint name="6" type="revolute">
    <origin rpy="1.5707963267948958919 -1.570796326794896336 0" xyz="0.014999999999999975159 0.014300000000000000211 -0.013000000000000018485"/>
    <parent link="pip_2"/>
    <child link="dip_2"/>
    <axis xyz="0 0 -1"/>
    <limit effort="0.95" lower="-0.506" upper="1.885" velocity="8.48"/>
    <joint_properties friction="0.0"/>
  </joint>
  <joint name="7" type="revolute">
    <origin rpy="4.5935029425113654229e-17 -2.8730071914463794583e-16 1.4408183216511868558e-31" xyz="1.0061396160665481148e-16 -0.036099999999999854428 0.00020000000000007858714"/>
    <parent link="dip_2"/>
    <child link="fingertip_2"/>
    <axis xyz="0 0 -1"/>
    <limit effort="0.95" lower="-0.366" upper="2.042" velocity="8.48"/>
    <joint_properties friction="0.0"/>
  </joint>
  <link name="mcp_joint_3">
    <visual>
      <origin rpy="1.6375789613220999807e-15 -1.0059504988632626953e-30 5.729641584552035421e-32" xyz="0.0084069022611744995133 0.0077662438597169963089 0.014657354985032913786"/>
      <geometry>
        <mesh filename="./leap_hand/mesh/mcp_joint.stl"/>
      </geometry>
      <material name="mcp_joint_material">
        <color rgba="0.86666666666666669627 0.86666666666666669627 0.050980392156862744391 1.0"/>
      </material>
    </visual>
    <collision>
      <origin rpy="1.6375789613220999807e-15 -1.0059504988632626953e-30 5.729641584552035421e-32" xyz="0.0084069022611744995133 0.0077662438597169963089 0.014657354985032913786"/>
      <geometry>
        <mesh filename="./leap_hand/mesh/mcp_joint.stl"/>
      </geometry>
    </collision>
    <inertial>
      <origin rpy="0 0 0" xyz="0 0 0"/>
      <mass value="0.044"/>
      <inertia ixx="0.000011499" ixy="0.000003049" ixz="0.000000121" iyy="0.000007796" iyz="0.000000112" izz="0.000014759"/>
    </inertial>
  </link>
  <link name="pip_3">
    <visual>
      <origin rpy="-1.570796326794896558 -1.570796326794896336 0" xyz="0.0096433630922713314826 0.00029999999999998083755 0.00078403401041737645627"/>
      <geometry>
        <mesh filename="./leap_hand/mesh/pip.stl"/>
      </geometry>
      <material name="pip_material">
        <color rgba="0.74901960784313725839 0.74901960784313725839 0.74901960784313725839 1.0"/>
      </material>
    </visual>
    <collision>
      <origin rpy="-1.570796326794896558 -1.570796326794896336 0" xyz="0.0096433630922713314826 0.00029999999999998083755 0.00078403401041737645627"/>
      <geometry>
        <mesh filename="./leap_hand/mesh/pip.stl"/>
      </geometry>
    </collision>
    <inertial>
      <origin rpy="0 0 0" xyz="0 0 0"/>
      <mass value="0.032"/>
      <inertia ixx="0.000004798" ixy="0.000000012" ixz="0.000000004" iyy="0.000002862" iyz="0.000000011" izz="0.000004234"/>
    </inertial>
  </link>
  <link name="dip_3">
    <visual>
      <origin rpy="-3.141592653589793116 -1.4095651113919093005e-33 1.5565411607615035382e-32" xyz="0.021133352895225006318 -0.0084321191467048653423 0.0097850881620952373519"/>
      <geometry>
        <mesh filename="./leap_hand/mesh/dip.stl"/>
      </geometry>
      <material name="dip_material">
        <color rgba="0.86666666666666669627 0.86666666666666669627 0.050980392156862744391 1.0"/>
      </material>
    </visual>
    <collision>
      <origin rpy="-3.141592653589793116 -1.4095651113919093005e-33 1.5565411607615035382e-32" xyz="0.021133352895225006318 -0.0084321191467048653423 0.0097850881620952373519"/>
      <geometry>
        <mesh filename="./leap_hand/mesh/dip.stl"/>
      </geometry>
    </collision>
    <inertial>
      <origin rpy="0 0 0" xyz="0 0 0"/>
      <mass value="0.037"/>
      <inertia ixx="0.000005542" ixy="-0.000000607" ixz="-0.000000017" iyy="0.000005727" iyz="-0.000000023" izz="0.000006682"/>
    </inertial>
  </link>
  <link name="fingertip_3">
    <visual>
      <origin rpy="3.141592653589793116 8.6170716950575402125e-33 1.5565411607615035382e-32" xyz="0.013286424108533501434 -0.0061142383865419869249 0.0144999999999994994"/>
      <geometry>
        <mesh filename="./leap_hand/mesh/fingertip.stl"/>
      </geometry>
      <material name="fingertip_material">
        <color rgba="0.86666666666666669627 0.86666666666666669627 0.050980392156862744391 1.0"/>
      </material>
    </visual>
    <collision>
      <origin rpy="3.141592653589793116 8.6170716950575402125e-33 1.5565411607615035382e-32" xyz="0.013286424108533501434 -0.0061142383865419869249 0.0144999999999994994"/>
      <geometry>
        <mesh filename="./leap_hand/mesh/fingertip.stl"/>
      </geometry>
    </collision>
    <inertial>
      <origin rpy="0 0 0" xyz="0 0 0"/>
      <mass value="0.016"/>
      <inertia ixx="0.000003368" ixy="0.000000115" ixz="0" iyy="0.000001556" iyz="0" izz="0.000002863"/>
    </inertial>
  </link>
  <joint name="8" type="revolute">
    <origin rpy="-1.570796326794896558 -1.0065212660796360242e-15 1.5707963267948943376" xyz="-0.012200000000000004244 0.038100000000000001921 0.014499999999999999001"/>
    <parent link="mcp_joint_3"/>
    <child link="pip_3"/>
    <axis xyz="0 0 -1"/>
    <limit effort="0.95" lower="-1.047" upper="1.047" velocity="8.48"/>
    <joint_properties friction="0.0"/>
  </joint>
  <joint name="9" type="revolute">
    <origin rpy="1.5707963267948950037 1.5707963267948945596 0" xyz="-0.0070952454426398371343 -0.067842243865100515521 -0.018722407666402932774"/>
    <parent link="palm_lower"/>
    <child link="mcp_joint_3"/>
    <axis xyz="0 0 -1"/>
    <limit effort="0.95" lower="-0.314" upper="2.23" velocity="8.48"/>
    <joint_properties friction="0.0"/>
  </joint>
  <joint name="10" type="revolute">
    <origin rpy="1.5707963267948958919 -1.570796326794896336 0" xyz="0.014999999999999971689 0.014299999999999951639 -0.012999999999999959505"/>
    <parent link="pip_3"/>
    <child link="dip_3"/>
    <axis xyz="0 0 -1"/>
    <limit effort="0.95" lower="-0.506" upper="1.885" velocity="8.48"/>
    <joint_properties friction="0.0"/>
  </joint>
  <joint name="11" type="revolute">
    <origin rpy="4.5935029425113685044e-17 -2.8730071914463799514e-16 1.5565411607615035382e-32" xyz="9.7144514654701197287e-17 -0.036099999999999868305 0.00020000000000007511769"/>
    <parent link="dip_3"/>
    <child link="fingertip_3"/>
    <axis xyz="0 0 -1"/>
    <limit effort="0.95" lower="-0.366" upper="2.042" velocity="8.48"/>
    <joint_properties friction="0.0"/>
  </joint>
  <link name="pip_4">
    <visual>
      <origin rpy="-1.570796326794896558 -1.570796326794896336 0" xyz="-0.0053566369077286714317 0.00029999999999999991951 0.00078403401041737819099"/>
      <geometry>
        <mesh filename="./leap_hand/mesh/pip.stl"/>
      </geometry>
      <material name="pip_material">
        <color rgba="0.74901960784313725839 0.74901960784313725839 0.74901960784313725839 1.0"/>
      </material>
    </visual>
    <collision>
      <origin rpy="-1.570796326794896558 -1.570796326794896336 0" xyz="-0.0053566369077286714317 0.00029999999999999991951 0.00078403401041737819099"/>
      <geometry>
        <mesh filename="./leap_hand/mesh/pip.stl"/>
      </geometry>
    </collision>
    <inertial>
      <origin rpy="0 0 0" xyz="0 0 0"/>
      <mass value="0.032"/>
      <inertia ixx="0.000004798" ixy="0.000000012" ixz="0.000000004" iyy="0.000002862" iyz="0.000000011" izz="0.000004234"/>
    </inertial>
  </link>
  <link name="thumb_pip">
    <visual>
      <origin rpy="1.570796326794896558 1.6050198443300152637e-46 -3.9204996250525192755e-59" xyz="0.011961920770611186859 -5.3082538364890297089e-16 -0.015852648956664199681"/>
      <geometry>
        <mesh filename="./leap_hand/mesh/thumb_pip.stl"/>
      </geometry>
      <material name="thumb_pip_material">
        <color rgba="0.86666666666666669627 0.86666666666666669627 0.050980392156862744391 1.0"/>
      </material>
    </visual>
    <collision>
      <origin rpy="1.570796326794896558 1.6050198443300152637e-46 -3.9204996250525192755e-59" xyz="0.011961920770611186859 -5.3082538364890297089e-16 -0.015852648956664199681"/>
      <geometry>
        <mesh filename="./leap_hand/mesh/thumb_pip.stl"/>
      </geometry>
    </collision>
    <inertial>
      <origin rpy="0 0 0" xyz="0 0 0"/>
      <mass value="0.003"/>
      <inertia ixx="0.000000593" ixy="0" ixz="0" iyy="0.000000549" iyz="0" izz="0.000000224"/>
    </inertial>
  </link>
  <link name="thumb_dip">
    <visual>
      <origin rpy="1.9428902930940098942e-16 3.2751579226442200773e-15 1.1123758529657360012e-46" xyz="0.043968715707239175439 0.057952952973709198625 -0.0086286764493694757122"/>
      <geometry>
        <mesh filename="./leap_hand/mesh/thumb_dip.stl"/>
      </geometry>
      <material name="thumb_dip_material">
        <color rgba="0.86666666666666669627 0.86666666666666669627 0.050980392156862744391 1.0"/>
      </material>
    </visual>
    <collision>
      <origin rpy="1.9428902930940098942e-16 3.2751579226442200773e-15 1.1123758529657360012e-46" xyz="0.043968715707239175439 0.057952952973709198625 -0.0086286764493694757122"/>
      <geometry>
        <mesh filename="./leap_hand/mesh/thumb_dip.stl"/>
      </geometry>
    </collision>
    <inertial>
      <origin rpy="0 0 0" xyz="0 0 0"/>
      <mass value="0.038"/>
      <inertia ixx="0.000008474" ixy="0.000000241" ixz="0.000000026" iyy="0.000003841" iyz="0.000000025" izz="0.000007679"/>
    </inertial>
  </link>
  <link name="thumb_fingertip">
    <visual>
      <origin rpy="4.3790577010156367543e-47 -3.3306690738754701143e-16 1.2042408677791935383e-46" xyz="0.062559538462667388381 0.078459682911396988469 0.048992911807332215068"/>
      <geometry>
        <mesh filename="./leap_hand/mesh/thumbtip_gelsight.STL"/>
      </geometry>
      <material name="thumb_fingertip_material">
        <color rgba="0.60392156862745094426 0.14901960784313725283 0.14901960784313725283 1.0"/>
      </material>
    </visual>
    <collision>
      <origin rpy="4.3790577010156367543e-47 -3.3306690738754701143e-16 1.2042408677791935383e-46" xyz="0.062559538462667388381 0.078459682911396988469 0.048992911807332215068"/>
      <geometry>
        <mesh filename="./leap_hand/mesh/thumbtip_gelsight.STL"/>
      </geometry>
    </collision>
    <inertial>
      <origin rpy="0 0 0" xyz="0 0 0"/>
      <mass value="0.049"/>
      <inertia ixx="0.000020372" ixy="-0.000000489" ixz="-0.00000003" iyy="0.000004336" iyz="-0.000000097" izz="0.000019845"/>
    </inertial>
  </link>
  <joint name="12" type="revolute">
    <origin rpy="-8.2381766464939424156e-17 1.5707963267948956698 0" xyz="-0.069395249652862533996 -0.0012422438651005258004 -0.021622403578460215601"/>
    <parent link="palm_lower"/>
    <child link="pip_4"/>
    <axis xyz="0 0 -1"/>
    <limit effort="0.95" lower="-0.349" upper="2.094" velocity="8.48"/>
    <joint_properties friction="0.0"/>
  </joint>
  <joint name="13" type="revolute">
    <origin rpy="1.5707963267948958919 -1.570796326794896336 0" xyz="-2.7755575615628913511e-17 0.014300000000000005415 -0.013000000000000011546"/>
    <parent link="pip_4"/>
    <child link="thumb_pip"/>
    <axis xyz="0 0 -1"/>
    <limit effort="0.95" lower="-0.47" upper="2.443" velocity="8.48"/>
    <joint_properties friction="0.0"/>
  </joint>
  <joint name="14" type="revolute">
    <origin rpy="-1.570796326794896558 1.6050198443300131245e-46 -1.9721522630516624601e-31" xyz="0 0.014499999999999966041 -0.017000000000000053263"/>
    <parent link="thumb_pip"/>
    <child link="thumb_dip"/>
    <axis xyz="0 0 -1"/>
    <limit effort="0.95" lower="-1.20" upper="1.90" velocity="8.48"/>
    <joint_properties friction="0.0"/>
  </joint>
  <joint name="15" type="revolute">
    <origin rpy="1.5063958491491781023e-44 5.4234187233935260503e-31 3.141592653589793116" xyz="-1.249000902703301108e-16 0.046599999999999863753 0.00019999999999997710581"/>
    <parent link="thumb_dip"/>
    <child link="thumb_fingertip"/>
    <axis xyz="0 0 -1"/>
    <limit effort="0.95" lower="-1.34" upper="1.88" velocity="8.48"/>
    <joint_properties friction="0.0"/>
  </joint>
  <joint name="ee_to_palm" type="fixed">
    <origin rpy="3.141592653589793 0 1.5707963267948966" xyz="0.025 0.060 0.015"/>
    <parent link="end_effector"/>
    <child link="palm_lower"/>
  </joint>
  <link name="finger0_tip_center"/>
  <link name="finger1_tip_center"/>
  <link name="finger2_tip_center"/>
  <link name="thumb_tip_center"/>
  <joint name="finger0_tip_base_to_center" type="fixed">
    <origin rpy="0 -1.5707963267948966 0" xyz="-0.020 -0.0425 0.0145"/>
    <parent link="fingertip"/>
    <child link="finger0_tip_center"/>
  </joint>
  <joint name="finger1_tip_base_to_center" type="fixed">
    <origin rpy="0 -1.5707963267948966 0" xyz="-0.01 -0.035 0.0145"/>
    <parent link="fingertip_2"/>
    <child link="finger1_tip_center"/>
  </joint>
  <joint name="finger2_tip_base_to_center" type="fixed">
    <origin rpy="0 -1.5707963267948966 0" xyz="-0.01 -0.035 0.0145"/>
    <parent link="fingertip_3"/>
    <child link="finger2_tip_center"/>
  </joint>
  <joint name="thumb_tip_base_to_center" type="fixed">
    <origin rpy="0 -1.5707963267948966 0" xyz="-0.020 -0.055 -0.0145"/>
    <parent link="thumb_fingertip"/>
    <child link="thumb_tip_center"/>
  </joint>
</robot>
